2021-02-16 00:04:35,892 ERROR: Exception on / [GET] [in /Users/cooper/Desktop/Websites/microblog/venv/lib/python3.9/site-packages/flask/app.py:1891]
Traceback (most recent call last):
  File "/Users/cooper/Desktop/Websites/microblog/venv/lib/python3.9/site-packages/flask/app.py", line 2447, in wsgi_app
    response = self.full_dispatch_request()
  File "/Users/cooper/Desktop/Websites/microblog/venv/lib/python3.9/site-packages/flask/app.py", line 1952, in full_dispatch_request
    rv = self.handle_user_exception(e)
  File "/Users/cooper/Desktop/Websites/microblog/venv/lib/python3.9/site-packages/flask/app.py", line 1821, in handle_user_exception
    reraise(exc_type, exc_value, tb)
  File "/Users/cooper/Desktop/Websites/microblog/venv/lib/python3.9/site-packages/flask/_compat.py", line 39, in reraise
    raise value
  File "/Users/cooper/Desktop/Websites/microblog/venv/lib/python3.9/site-packages/flask/app.py", line 1950, in full_dispatch_request
    rv = self.dispatch_request()
  File "/Users/cooper/Desktop/Websites/microblog/venv/lib/python3.9/site-packages/flask/app.py", line 1936, in dispatch_request
    return self.view_functions[rule.endpoint](**req.view_args)
  File "/Users/cooper/Desktop/Websites/microblog/venv/lib/python3.9/site-packages/flask_login/utils.py", line 272, in decorated_view
    return func(*args, **kwargs)
  File "/Users/cooper/Desktop/Websites/microblog/app/routes.py", line 31, in index
    return render_template('index.html', title='Home Page', form=form, posts=posts)
  File "/Users/cooper/Desktop/Websites/microblog/venv/lib/python3.9/site-packages/flask/templating.py", line 137, in render_template
    return _render(
  File "/Users/cooper/Desktop/Websites/microblog/venv/lib/python3.9/site-packages/flask/templating.py", line 120, in _render
    rv = template.render(context)
  File "/Users/cooper/Desktop/Websites/microblog/venv/lib/python3.9/site-packages/jinja2/environment.py", line 1090, in render
    self.environment.handle_exception()
  File "/Users/cooper/Desktop/Websites/microblog/venv/lib/python3.9/site-packages/jinja2/environment.py", line 832, in handle_exception
    reraise(*rewrite_traceback_stack(source=source))
  File "/Users/cooper/Desktop/Websites/microblog/venv/lib/python3.9/site-packages/jinja2/_compat.py", line 28, in reraise
    raise value.with_traceback(tb)
  File "/Users/cooper/Desktop/Websites/microblog/app/templates/index.html", line 1, in top-level template code
    {% extends "base.html" %}
  File "/Users/cooper/Desktop/Websites/microblog/venv/lib/python3.9/site-packages/jinja2/environment.py", line 832, in handle_exception
    reraise(*rewrite_traceback_stack(source=source))
  File "/Users/cooper/Desktop/Websites/microblog/venv/lib/python3.9/site-packages/jinja2/_compat.py", line 28, in reraise
    raise value.with_traceback(tb)
  File "/Users/cooper/Desktop/Websites/microblog/app/templates/base.html", line 19, in template
    <a href="{{ url_for('explore) }}">Explore</a>
jinja2.exceptions.TemplateSyntaxError: unexpected char "'" at 611
2021-02-16 00:05:26,731 INFO: Microblog startup [in /Users/cooper/Desktop/Websites/microblog/app/__init__.py:51]
2021-02-16 00:05:56,420 ERROR: Exception on /login [GET] [in /Users/cooper/Desktop/Websites/microblog/venv/lib/python3.9/site-packages/flask/app.py:1891]
Traceback (most recent call last):
  File "/Users/cooper/Desktop/Websites/microblog/venv/lib/python3.9/site-packages/flask/app.py", line 2447, in wsgi_app
    response = self.full_dispatch_request()
  File "/Users/cooper/Desktop/Websites/microblog/venv/lib/python3.9/site-packages/flask/app.py", line 1952, in full_dispatch_request
    rv = self.handle_user_exception(e)
  File "/Users/cooper/Desktop/Websites/microblog/venv/lib/python3.9/site-packages/flask/app.py", line 1821, in handle_user_exception
    reraise(exc_type, exc_value, tb)
  File "/Users/cooper/Desktop/Websites/microblog/venv/lib/python3.9/site-packages/flask/_compat.py", line 39, in reraise
    raise value
  File "/Users/cooper/Desktop/Websites/microblog/venv/lib/python3.9/site-packages/flask/app.py", line 1950, in full_dispatch_request
    rv = self.dispatch_request()
  File "/Users/cooper/Desktop/Websites/microblog/venv/lib/python3.9/site-packages/flask/app.py", line 1936, in dispatch_request
    return self.view_functions[rule.endpoint](**req.view_args)
  File "/Users/cooper/Desktop/Websites/microblog/app/routes.py", line 59, in login
    return render_template('login.html', title='Sign In', form=fo)
NameError: name 'fo' is not defined
2021-02-16 00:07:03,265 INFO: Microblog startup [in /Users/cooper/Desktop/Websites/microblog/app/__init__.py:51]
2021-02-16 00:14:41,660 INFO: Microblog startup [in /Users/cooper/Desktop/Websites/microblog/app/__init__.py:51]
2021-02-16 00:15:54,261 INFO: Microblog startup [in /Users/cooper/Desktop/Websites/microblog/app/__init__.py:51]
2021-02-16 00:19:56,096 INFO: Microblog startup [in /Users/cooper/Desktop/Websites/microblog/app/__init__.py:51]
2021-02-16 00:38:39,597 INFO: Microblog startup [in /Users/cooper/Desktop/Websites/microblog/app/__init__.py:51]
2021-02-16 00:58:44,945 INFO: Microblog startup [in /Users/cooper/Desktop/Websites/microblog/app/__init__.py:51]
2021-02-16 01:00:13,410 INFO: Microblog startup [in /Users/cooper/Desktop/Websites/microblog/app/__init__.py:51]
2021-02-16 01:00:16,367 ERROR: Exception on /explore [GET] [in /Users/cooper/Desktop/Websites/microblog/venv/lib/python3.9/site-packages/flask/app.py:1891]
Traceback (most recent call last):
  File "/Users/cooper/Desktop/Websites/microblog/venv/lib/python3.9/site-packages/flask/app.py", line 2447, in wsgi_app
    response = self.full_dispatch_request()
  File "/Users/cooper/Desktop/Websites/microblog/venv/lib/python3.9/site-packages/flask/app.py", line 1952, in full_dispatch_request
    rv = self.handle_user_exception(e)
  File "/Users/cooper/Desktop/Websites/microblog/venv/lib/python3.9/site-packages/flask/app.py", line 1821, in handle_user_exception
    reraise(exc_type, exc_value, tb)
  File "/Users/cooper/Desktop/Websites/microblog/venv/lib/python3.9/site-packages/flask/_compat.py", line 39, in reraise
    raise value
  File "/Users/cooper/Desktop/Websites/microblog/venv/lib/python3.9/site-packages/flask/app.py", line 1950, in full_dispatch_request
    rv = self.dispatch_request()
  File "/Users/cooper/Desktop/Websites/microblog/venv/lib/python3.9/site-packages/flask/app.py", line 1936, in dispatch_request
    return self.view_functions[rule.endpoint](**req.view_args)
  File "/Users/cooper/Desktop/Websites/microblog/venv/lib/python3.9/site-packages/flask_login/utils.py", line 272, in decorated_view
    return func(*args, **kwargs)
  File "/Users/cooper/Desktop/Websites/microblog/app/routes.py", line 47, in explore
    posts = Post.query.order_by(Post.timestamp.desc()).paginate(
  File "/Users/cooper/Desktop/Websites/microblog/venv/lib/python3.9/site-packages/flask_sqlalchemy/__init__.py", line 484, in paginate
    if page < 1:
TypeError: '<' not supported between instances of 'type' and 'int'
2021-02-16 01:01:14,596 ERROR: Exception on /explore [GET] [in /Users/cooper/Desktop/Websites/microblog/venv/lib/python3.9/site-packages/flask/app.py:1891]
Traceback (most recent call last):
  File "/Users/cooper/Desktop/Websites/microblog/venv/lib/python3.9/site-packages/flask/app.py", line 2447, in wsgi_app
    response = self.full_dispatch_request()
  File "/Users/cooper/Desktop/Websites/microblog/venv/lib/python3.9/site-packages/flask/app.py", line 1952, in full_dispatch_request
    rv = self.handle_user_exception(e)
  File "/Users/cooper/Desktop/Websites/microblog/venv/lib/python3.9/site-packages/flask/app.py", line 1821, in handle_user_exception
    reraise(exc_type, exc_value, tb)
  File "/Users/cooper/Desktop/Websites/microblog/venv/lib/python3.9/site-packages/flask/_compat.py", line 39, in reraise
    raise value
  File "/Users/cooper/Desktop/Websites/microblog/venv/lib/python3.9/site-packages/flask/app.py", line 1950, in full_dispatch_request
    rv = self.dispatch_request()
  File "/Users/cooper/Desktop/Websites/microblog/venv/lib/python3.9/site-packages/flask/app.py", line 1936, in dispatch_request
    return self.view_functions[rule.endpoint](**req.view_args)
  File "/Users/cooper/Desktop/Websites/microblog/venv/lib/python3.9/site-packages/flask_login/utils.py", line 272, in decorated_view
    return func(*args, **kwargs)
  File "/Users/cooper/Desktop/Websites/microblog/app/routes.py", line 47, in explore
    posts = Post.query.order_by(Post.timestamp.desc()).paginate(
  File "/Users/cooper/Desktop/Websites/microblog/venv/lib/python3.9/site-packages/flask_sqlalchemy/__init__.py", line 484, in paginate
    if page < 1:
TypeError: '<' not supported between instances of 'type' and 'int'
