2021-02-19 00:40:35,865 ERROR: Exception on /user/cooperchen12 [GET] [in /Users/cooper/Desktop/Websites/microblog/venv/lib/python3.9/site-packages/flask/app.py:1891]
Traceback (most recent call last):
  File "/Users/cooper/Desktop/Websites/microblog/venv/lib/python3.9/site-packages/flask/app.py", line 2447, in wsgi_app
    response = self.full_dispatch_request()
  File "/Users/cooper/Desktop/Websites/microblog/venv/lib/python3.9/site-packages/flask/app.py", line 1952, in full_dispatch_request
    rv = self.handle_user_exception(e)
  File "/Users/cooper/Desktop/Websites/microblog/venv/lib/python3.9/site-packages/flask/app.py", line 1821, in handle_user_exception
    reraise(exc_type, exc_value, tb)
  File "/Users/cooper/Desktop/Websites/microblog/venv/lib/python3.9/site-packages/flask/_compat.py", line 39, in reraise
    raise value
  File "/Users/cooper/Desktop/Websites/microblog/venv/lib/python3.9/site-packages/flask/app.py", line 1950, in full_dispatch_request
    rv = self.dispatch_request()
  File "/Users/cooper/Desktop/Websites/microblog/venv/lib/python3.9/site-packages/flask/app.py", line 1936, in dispatch_request
    return self.view_functions[rule.endpoint](**req.view_args)
  File "/Users/cooper/Desktop/Websites/microblog/venv/lib/python3.9/site-packages/flask_login/utils.py", line 272, in decorated_view
    return func(*args, **kwargs)
  File "/Users/cooper/Desktop/Websites/microblog/app/routes.py", line 114, in user
    return render_template('user.html', user=user, posts=posts.items,
  File "/Users/cooper/Desktop/Websites/microblog/venv/lib/python3.9/site-packages/flask/templating.py", line 137, in render_template
    return _render(
  File "/Users/cooper/Desktop/Websites/microblog/venv/lib/python3.9/site-packages/flask/templating.py", line 120, in _render
    rv = template.render(context)
  File "/Users/cooper/Desktop/Websites/microblog/venv/lib/python3.9/site-packages/jinja2/environment.py", line 1090, in render
    self.environment.handle_exception()
  File "/Users/cooper/Desktop/Websites/microblog/venv/lib/python3.9/site-packages/jinja2/environment.py", line 832, in handle_exception
    reraise(*rewrite_traceback_stack(source=source))
  File "/Users/cooper/Desktop/Websites/microblog/venv/lib/python3.9/site-packages/jinja2/_compat.py", line 28, in reraise
    raise value.with_traceback(tb)
  File "/Users/cooper/Desktop/Websites/microblog/app/templates/user.html", line 1, in top-level template code
    {% extends "base.html" %}
  File "/Users/cooper/Desktop/Websites/microblog/app/templates/base.html", line 1, in top-level template code
    {% extends 'bootstrap/base.html' %}
  File "/Users/cooper/Desktop/Websites/microblog/venv/lib/python3.9/site-packages/flask_bootstrap/templates/bootstrap/base.html", line 1, in top-level template code
    {% block doc -%}
  File "/Users/cooper/Desktop/Websites/microblog/venv/lib/python3.9/site-packages/flask_bootstrap/templates/bootstrap/base.html", line 4, in block "doc"
    {%- block html %}
  File "/Users/cooper/Desktop/Websites/microblog/venv/lib/python3.9/site-packages/flask_bootstrap/templates/bootstrap/base.html", line 20, in block "html"
    {% block body -%}
  File "/Users/cooper/Desktop/Websites/microblog/venv/lib/python3.9/site-packages/flask_bootstrap/templates/bootstrap/base.html", line 23, in block "body"
    {% block content -%}
  File "/Users/cooper/Desktop/Websites/microblog/app/templates/base.html", line 48, in block "content"
    {% block app_content %}{% endblock %}
  File "/Users/cooper/Desktop/Websites/microblog/app/templates/user.html", line 11, in block "app_content"
    <p>{{ user.followers.count() }} followers, {{ user.followed.count() }} following.</p>
  File "/Users/cooper/Desktop/Websites/microblog/venv/lib/python3.9/site-packages/jinja2/environment.py", line 471, in getattr
    return getattr(obj, attribute)
jinja2.exceptions.UndefinedError: 'app.models.User object' has no attribute 'followed'
2021-02-19 00:44:50,917 INFO: Microblog startup [in /Users/cooper/Desktop/Websites/microblog/app/__init__.py:59]
2021-02-19 01:48:53,056 INFO: Microblog startup [in /Users/cooper/Desktop/Websites/microblog/app/__init__.py:63]
2021-02-19 14:28:58,905 INFO: Microblog startup [in /Users/cooper/Desktop/Websites/microblog/app/__init__.py:67]
2021-02-19 14:29:30,480 INFO: Microblog startup [in /Users/cooper/Desktop/Websites/microblog/app/__init__.py:67]
2021-02-19 14:29:32,069 ERROR: Exception on /user/cooperchen12 [GET] [in /Users/cooper/Desktop/Websites/microblog/venv/lib/python3.9/site-packages/flask/app.py:1891]
Traceback (most recent call last):
  File "/Users/cooper/Desktop/Websites/microblog/venv/lib/python3.9/site-packages/flask/app.py", line 2447, in wsgi_app
    response = self.full_dispatch_request()
  File "/Users/cooper/Desktop/Websites/microblog/venv/lib/python3.9/site-packages/flask/app.py", line 1952, in full_dispatch_request
    rv = self.handle_user_exception(e)
  File "/Users/cooper/Desktop/Websites/microblog/venv/lib/python3.9/site-packages/flask/app.py", line 1821, in handle_user_exception
    reraise(exc_type, exc_value, tb)
  File "/Users/cooper/Desktop/Websites/microblog/venv/lib/python3.9/site-packages/flask/_compat.py", line 39, in reraise
    raise value
  File "/Users/cooper/Desktop/Websites/microblog/venv/lib/python3.9/site-packages/flask/app.py", line 1948, in full_dispatch_request
    rv = self.preprocess_request()
  File "/Users/cooper/Desktop/Websites/microblog/venv/lib/python3.9/site-packages/flask/app.py", line 2242, in preprocess_request
    rv = func()
  File "/Users/cooper/Desktop/Websites/microblog/app/routes.py", line 18, in before_request
    g.locale = str(get_locale())
  File "/Users/cooper/Desktop/Websites/microblog/venv/lib/python3.9/site-packages/flask_babel/__init__.py", line 230, in get_locale
    locale = Locale.parse(rv)
  File "/Users/cooper/Desktop/Websites/microblog/venv/lib/python3.9/site-packages/babel/core.py", line 268, in parse
    parts = parse_locale(identifier, sep=sep)
  File "/Users/cooper/Desktop/Websites/microblog/venv/lib/python3.9/site-packages/babel/core.py", line 1094, in parse_locale
    raise ValueError('expected only letters, got %r' % lang)
ValueError: expected only letters, got 'en-us'
2021-02-19 14:30:45,799 INFO: Microblog startup [in /Users/cooper/Desktop/Websites/microblog/app/__init__.py:67]
2021-02-19 14:30:47,168 ERROR: Exception on /user/cooperchen12 [GET] [in /Users/cooper/Desktop/Websites/microblog/venv/lib/python3.9/site-packages/flask/app.py:1891]
Traceback (most recent call last):
  File "/Users/cooper/Desktop/Websites/microblog/venv/lib/python3.9/site-packages/flask/app.py", line 2447, in wsgi_app
    response = self.full_dispatch_request()
  File "/Users/cooper/Desktop/Websites/microblog/venv/lib/python3.9/site-packages/flask/app.py", line 1952, in full_dispatch_request
    rv = self.handle_user_exception(e)
  File "/Users/cooper/Desktop/Websites/microblog/venv/lib/python3.9/site-packages/flask/app.py", line 1821, in handle_user_exception
    reraise(exc_type, exc_value, tb)
  File "/Users/cooper/Desktop/Websites/microblog/venv/lib/python3.9/site-packages/flask/_compat.py", line 39, in reraise
    raise value
  File "/Users/cooper/Desktop/Websites/microblog/venv/lib/python3.9/site-packages/flask/app.py", line 1948, in full_dispatch_request
    rv = self.preprocess_request()
  File "/Users/cooper/Desktop/Websites/microblog/venv/lib/python3.9/site-packages/flask/app.py", line 2242, in preprocess_request
    rv = func()
  File "/Users/cooper/Desktop/Websites/microblog/app/routes.py", line 18, in before_request
    g.locale = str(get_locale())
NameError: name 'g' is not defined
2021-02-19 14:31:09,115 INFO: Microblog startup [in /Users/cooper/Desktop/Websites/microblog/app/__init__.py:67]
