2021-02-16 16:02:27,392 ERROR: Exception on /reset_password_request [POST] [in /Users/cooper/Desktop/Websites/microblog/venv/lib/python3.9/site-packages/flask/app.py:1891]
Traceback (most recent call last):
  File "/Users/cooper/Desktop/Websites/microblog/venv/lib/python3.9/site-packages/flask/app.py", line 2447, in wsgi_app
    response = self.full_dispatch_request()
  File "/Users/cooper/Desktop/Websites/microblog/venv/lib/python3.9/site-packages/flask/app.py", line 1952, in full_dispatch_request
    rv = self.handle_user_exception(e)
  File "/Users/cooper/Desktop/Websites/microblog/venv/lib/python3.9/site-packages/flask/app.py", line 1821, in handle_user_exception
    reraise(exc_type, exc_value, tb)
  File "/Users/cooper/Desktop/Websites/microblog/venv/lib/python3.9/site-packages/flask/_compat.py", line 39, in reraise
    raise value
  File "/Users/cooper/Desktop/Websites/microblog/venv/lib/python3.9/site-packages/flask/app.py", line 1950, in full_dispatch_request
    rv = self.dispatch_request()
  File "/Users/cooper/Desktop/Websites/microblog/venv/lib/python3.9/site-packages/flask/app.py", line 1936, in dispatch_request
    return self.view_functions[rule.endpoint](**req.view_args)
  File "/Users/cooper/Desktop/Websites/microblog/app/routes.py", line 185, in reset_password_request
    send_password_reset_email(user)
  File "/Users/cooper/Desktop/Websites/microblog/app/email.py", line 17, in send_password_reset_email
    user=iser, token=token),
NameError: name 'iser' is not defined
2021-02-16 16:03:01,237 INFO: Microblog startup [in /Users/cooper/Desktop/Websites/microblog/app/__init__.py:55]
2021-02-16 16:03:09,661 ERROR: Exception on /reset_password_request [POST] [in /Users/cooper/Desktop/Websites/microblog/venv/lib/python3.9/site-packages/flask/app.py:1891]
Traceback (most recent call last):
  File "/Users/cooper/Desktop/Websites/microblog/venv/lib/python3.9/site-packages/flask/app.py", line 2447, in wsgi_app
    response = self.full_dispatch_request()
  File "/Users/cooper/Desktop/Websites/microblog/venv/lib/python3.9/site-packages/flask/app.py", line 1952, in full_dispatch_request
    rv = self.handle_user_exception(e)
  File "/Users/cooper/Desktop/Websites/microblog/venv/lib/python3.9/site-packages/flask/app.py", line 1821, in handle_user_exception
    reraise(exc_type, exc_value, tb)
  File "/Users/cooper/Desktop/Websites/microblog/venv/lib/python3.9/site-packages/flask/_compat.py", line 39, in reraise
    raise value
  File "/Users/cooper/Desktop/Websites/microblog/venv/lib/python3.9/site-packages/flask/app.py", line 1950, in full_dispatch_request
    rv = self.dispatch_request()
  File "/Users/cooper/Desktop/Websites/microblog/venv/lib/python3.9/site-packages/flask/app.py", line 1936, in dispatch_request
    return self.view_functions[rule.endpoint](**req.view_args)
  File "/Users/cooper/Desktop/Websites/microblog/app/routes.py", line 185, in reset_password_request
    send_password_reset_email(user)
  File "/Users/cooper/Desktop/Websites/microblog/app/email.py", line 17, in send_password_reset_email
    user=iser, token=token),
NameError: name 'iser' is not defined
2021-02-16 16:03:18,249 INFO: Microblog startup [in /Users/cooper/Desktop/Websites/microblog/app/__init__.py:55]
2021-02-16 16:03:23,171 ERROR: Exception on /reset_password_request [POST] [in /Users/cooper/Desktop/Websites/microblog/venv/lib/python3.9/site-packages/flask/app.py:1891]
Traceback (most recent call last):
  File "/Users/cooper/Desktop/Websites/microblog/venv/lib/python3.9/site-packages/flask_mail.py", line 492, in send
    message.send(connection)
  File "/Users/cooper/Desktop/Websites/microblog/venv/lib/python3.9/site-packages/flask_mail.py", line 427, in send
    connection.send(self)
  File "/Users/cooper/Desktop/Websites/microblog/venv/lib/python3.9/site-packages/flask_mail.py", line 188, in send
    self.host.sendmail(sanitize_address(envelope_from or message.sender),
  File "/Library/Frameworks/Python.framework/Versions/3.9/lib/python3.9/smtplib.py", line 856, in sendmail
    self.ehlo_or_helo_if_needed()
  File "/Library/Frameworks/Python.framework/Versions/3.9/lib/python3.9/smtplib.py", line 604, in ehlo_or_helo_if_needed
    if not (200 <= self.ehlo()[0] <= 299):
  File "/Library/Frameworks/Python.framework/Versions/3.9/lib/python3.9/smtplib.py", line 444, in ehlo
    self.putcmd(self.ehlo_msg, name or self.local_hostname)
  File "/Library/Frameworks/Python.framework/Versions/3.9/lib/python3.9/smtplib.py", line 371, in putcmd
    self.send(str)
  File "/Library/Frameworks/Python.framework/Versions/3.9/lib/python3.9/smtplib.py", line 363, in send
    raise SMTPServerDisconnected('please run connect() first')
smtplib.SMTPServerDisconnected: please run connect() first

During handling of the above exception, another exception occurred:

Traceback (most recent call last):
  File "/Users/cooper/Desktop/Websites/microblog/venv/lib/python3.9/site-packages/flask/app.py", line 2447, in wsgi_app
    response = self.full_dispatch_request()
  File "/Users/cooper/Desktop/Websites/microblog/venv/lib/python3.9/site-packages/flask/app.py", line 1952, in full_dispatch_request
    rv = self.handle_user_exception(e)
  File "/Users/cooper/Desktop/Websites/microblog/venv/lib/python3.9/site-packages/flask/app.py", line 1821, in handle_user_exception
    reraise(exc_type, exc_value, tb)
  File "/Users/cooper/Desktop/Websites/microblog/venv/lib/python3.9/site-packages/flask/_compat.py", line 39, in reraise
    raise value
  File "/Users/cooper/Desktop/Websites/microblog/venv/lib/python3.9/site-packages/flask/app.py", line 1950, in full_dispatch_request
    rv = self.dispatch_request()
  File "/Users/cooper/Desktop/Websites/microblog/venv/lib/python3.9/site-packages/flask/app.py", line 1936, in dispatch_request
    return self.view_functions[rule.endpoint](**req.view_args)
  File "/Users/cooper/Desktop/Websites/microblog/app/routes.py", line 185, in reset_password_request
    send_password_reset_email(user)
  File "/Users/cooper/Desktop/Websites/microblog/app/email.py", line 13, in send_password_reset_email
    send_email('[Microblog] Reset Your Password',
  File "/Users/cooper/Desktop/Websites/microblog/app/email.py", line 9, in send_email
    mail.send(msg)
  File "/Users/cooper/Desktop/Websites/microblog/venv/lib/python3.9/site-packages/flask_mail.py", line 492, in send
    message.send(connection)
  File "/Users/cooper/Desktop/Websites/microblog/venv/lib/python3.9/site-packages/flask_mail.py", line 152, in __exit__
    self.host.quit()
  File "/Library/Frameworks/Python.framework/Versions/3.9/lib/python3.9/smtplib.py", line 988, in quit
    res = self.docmd("quit")
  File "/Library/Frameworks/Python.framework/Versions/3.9/lib/python3.9/smtplib.py", line 424, in docmd
    self.putcmd(cmd, args)
  File "/Library/Frameworks/Python.framework/Versions/3.9/lib/python3.9/smtplib.py", line 371, in putcmd
    self.send(str)
  File "/Library/Frameworks/Python.framework/Versions/3.9/lib/python3.9/smtplib.py", line 363, in send
    raise SMTPServerDisconnected('please run connect() first')
smtplib.SMTPServerDisconnected: please run connect() first
2021-02-16 16:10:32,363 INFO: Microblog startup [in /Users/cooper/Desktop/Websites/microblog/app/__init__.py:55]
2021-02-16 16:20:19,383 INFO: Microblog startup [in /Users/cooper/Desktop/Websites/microblog/app/__init__.py:55]
